Workbook
Name Slicer_Account_Type: #N/A
Name Slicer_KYC_Status: #N/A

Sheet Raw Data
A1: Full Name | B1: Username | C1: Account Type | D1: Country | E1: City | F1: Age | G1: Gender | H1: Email | I1: Phone Number | J1: Account Creation Date | K1: Last Active Date | L1: Balance (USD) | M1: Debt (USD) | N1: Credit Score | O1: Income Level (USD Annual) | P1: Risk Category | Q1: KYC Status | R1: Fraud Flag | S1: Account Status
A2: Carlos M. Rivera Jr. | B2: carlos_rivera23 | C2: Premium | D2: US | E2: New York | F2: 42 | G2: Male | H2: carlos.rivera23@email.com | I2: =1-718-555-199 -> -1471 | J2: 43539 | K2: 45303 | L2: 45250.75 | M2: 12500.5 | N2: 745 | O2: 85000 | P2: Medium | Q2: Verified | R2: 0 | S2: Active
A3: Aiko Tanaka | B3: aiko_tanaka | C3: Digital-Only | D3: Japan | E3: Tokyo | F3: 28 | G3: Female | H3: aiko.tanaka@mail.jp | I3: =81-90-1234-5678 -> -6921 | J3: 44764 | K3: 45305 | L3: 12800 | M3: 3500.25 | N3: 810 | O3: 45000 | P3: Low | Q3: Verified | R3: 0 | S3: Active
A4: Md. Rahim Uddin | B4: rahim_uddin | C4: Business | D4: India | E4: Mumbai | F4: 35 | G4: Male | H4: rahim.uddin@business.in | I4: =91-987-654-3210 -> -4760 | J4: 44140 | K4: 45301 | L4: 87500.8 | M4: 45000.75 | N4: 680 | O4: 120000 | P4: Medium | Q4: Pending | R4: 0 | S4: Active
A5: Anna-Louise Clarke | B5: anna_clarke | C5: Joint | D5: UK | E5: London | F5: 31 | G5: Female | H5: anna.clarke@email.co.uk | I5: =44-20-7946-958 -> -8880 | J5: 44457 | K5: 45304 | L5: 25600.3 | M5: 18000 | N5: 720 | O5: 75000 | P5: Low | Q5: Verified | R5: 0 | S5: Active
A6: John 'Jack' Thompson | B6: jack_thompson | C6: Savings | D6: US | E6: Chicago | F6: 45 | G6: Male | H6: jack.thompson@email.com | I6: =1-312-555-123 -> -989 | J6: 43250 | K6: 45302 | L6: 67500.45 | M6: 25000.8 | N6: 695 | O6: 95000 | P6: Medium | Q6: Verified | R6: 0 | S6: Active
A7: Wei Zhang | B7: wei_zhang95 | C7: Current | D7: China | E7: Shanghai | F7: 26 | G7: Male | H7: wei.zhang@mail.cn | I7: =86-138-13-8000 -> -8065 | J7: 44971 | K7: 45306 | L7: 9800.25 | M7: 4200.5 | N7: 780 | O7: 38000 | P7: Low | Q7: Verified | R7: 0 | S7: Active
A8: Maria Silva Santos | B8: maria_silva | C8: Savings | D8: Brazil | E8: SÃ£o Paulo | F8: 39 | G8: Female | H8: maria.santos@email.com.br | I8: =55-11-91234-5678 -> -96868 | J8: 43689 | K8: 45300 | L8: 32400.6 | M8: 15800.25 | N8: 710 | O8: 68000 | P8: Medium | Q8: Verified | R8: 0 | S8: Active
A9: Chiamaka Okoro | B9: chiamaka_o | C9: Digital-Only | D9: Nigeria | E9: Lagos | F9: 24 | G9: Female | H9: chiamaka.okoro@mail.ng | I9: =234-703-456-7890 -> -8815 | J9: 45066 | K9: 45305 | L9: 5600.75 | M9: 3200 | N9: 650 | O9: 29000 | P9: Medium | Q9: Pending | R9: 0 | S9: Active
A10: Hans MÃ¼ller | B10: hans_muller | C10: Business | D10: Germany | E10: Berlin | F10: 52 | G10: Male | H10: hans.muller@company.de | I10: =49-170-1234567 -> -1234688 | J10: 43072 | K10: 45299 | L10: 124500.9 | M10: 75000.4 | N10: 665 | O10: 150000 | P10: High | Q10: Verified | R10: 0 | S10: Active
A11: Fatima Al Mansouri | B11: fatima_alm | C11: Joint | D11: UAE | E11: Dubai | F11: 36 | G11: Female | H11: fatima.mansouri@email.ae | I11: =971-50-345-6789 -> -6213 | J11: 44311 | K11: 45303 | L11: 78900.25 | M11: 32000.75 | N11: 730 | O11: 110000 | P11: Medium | Q11: Verified | R11: 0 | S11: Active
A12: James Wilson-Smith | B12: james_wilson | C12: Student | D12: Canada | E12: Toronto | F12: 21 | G12: Male | H12: james.wilson@edu.ca | I12: =1-416-555-189 -> -1159 | J12: 45179 | K12: 45304 | L12: 3200.5 | M12: 12500.8 | N12: 625 | O12: 22000 | P12: High | Q12: Pending | R12: 0 | S12: Active
A13: Yuki Nakamura | B13: yuki_nakamura | C13: Premium | D13: Japan | E13: Osaka | F13: 48 | G13: Female | H13: yuki.nakamura@mail.jp | I13: =81-80-9876-5432 -> -15307 | J13: 43847 | K13: 45301 | L13: 95600.4 | M13: 28000.6 | N13: 775 | O13: 125000 | P13: Low | Q13: Verified | R13: 0 | S13: Active
A14: Rajesh Kumar Patel | B14: rajesh_patel | C14: Savings | D14: India | E14: Delhi | F14: 33 | G14: Male | H14: rajesh.patel@email.in | I14: =91-989-876-5432 -> -7206 | J14: 44530 | K14: 45302 | L14: 42300.8 | M14: 19500.25 | N14: 690 | O14: 78000 | P14: Medium | Q14: Verified | R14: 0 | S14: Active
A15: Sarah Johnson-Williams | B15: sarah_jw | C15: Current | D15: UK | E15: Manchester | F15: 29 | G15: Female | H15: sarah.jw@email.co.uk | I15: =44-16-1837-4650 -> -6459 | J15: 44642 | K15: 45305 | L15: 15800.9 | M15: 8200.75 | N15: 745 | O15: 52000 | P15: Low | Q15: Verified | R15: 0 | S15: Active
A16: Mohammed Hassan | B16: mohammed_h | C16: Business | D16: UAE | E16: Abu Dhabi | F16: 44 | G16: Male | H16: mohammed.hassan@business.ae | I16: =971-56-789-123 -> 3 | J16: 43300 | K16: 45300 | L16: 187600.3 | M16: 92000.8 | N16: 655 | O16: 180000 | P16: High | Q16: Verified | R16: 0 | S16: Active
A17: Luciana Costa | B17: lucia_costa | C17: Digital-Only | D17: Brazil | E17: Rio de Janeiro | F17: 27 | G17: Female | H17: luciana.costa@mail.br | I17: =55-21-99876-5432 -> -105274 | J17: 44941 | K17: 45306 | L17: 7200.4 | M17: 4800.9 | N17: 720 | O17: 41000 | P17: Low | Q17: Verified | R17: 0 | S17: Active
A18: Kenji Sato | B18: kenji_sato | C18: Premium | D18: Japan | E18: Kyoto | F18: 55 | G18: Male | H18: kenji.sato@company.jp | I18: =81-75-234-5678 -> -5906 | J18: 42641 | K18: 45299 | L18: 203400.75 | M18: 45000.25 | N18: 805 | O18: 220000 | P18: Low | Q18: Verified | R18: 0 | S18: Active
A19: Adebola Okafor | B19: adebola_o | C19: Savings | D19: Nigeria | E19: Abuja | F19: 38 | G19: Male | H19: adebola.okafor@email.ng | I19: =234-802-345-6789 -> -7702 | J19: 43996 | K19: 45303 | L19: 28900.6 | M19: 13400.8 | N19: 675 | O19: 72000 | P19: Medium | Q19: Verified | R19: 0 | S19: Active
A20: Emma-Rose Gallagher | B20: emma_rose | C20: Student | D20: US | E20: Los Angeles | F20: 20 | G20: Female | H20: emma.gallagher@edu.com | I20: =1-213-555-176 -> -943 | J20: 45143 | K20: 45304 | L20: 1850.25 | M20: 9500.4 | N20: 610 | O20: 18000 | P20: High | Q20: Pending | R20: 0 | S20: Active
A21: Chen Wei | B21: chen_wei88 | C21: Current | D21: China | E21: Beijing | F21: 32 | G21: Male | H21: chen.wei@mail.cn | I21: =86-139-8765-4321 -> -13139 | J21: 44255 | K21: 45301 | L21: 24300.7 | M21: 11200.5 | N21: 760 | O21: 67000 | P21: Low | Q21: Verified | R21: 0 | S21: Active
A22: Sophie Schmidt | B22: sophie_schmidt | C22: Savings | D22: Germany | E22: Hamburg | F22: 41 | G22: Female | H22: sophie.schmidt@email.de | I22: =49-171-9876543 -> -9876665 | J22: 43573 | K22: 45302 | L22: 38700.25 | M22: 14500.6 | N22: 735 | O22: 89000 | P22: Low | Q22: Verified | R22: 0 | S22: Active
A23: David Chen-Li | B23: david_chenli | C23: Joint | D23: Canada | E23: Vancouver | F23: 37 | G23: Male | H23: david.chenli@email.ca | I23: =1-604-555-167 -> -1325 | J23: 44126 | K23: 45300 | L23: 54200.8 | M23: 22800.75 | N23: 710 | O23: 105000 | P23: Medium | Q23: Verified | R23: 0 | S23: Active
A24: Priya Sharma | B24: priya_sharma | C24: Digital-Only | D24: India | E24: Bangalore | F24: 26 | G24: Female | H24: priya.sharma@mail.in | I24: =91-876-543-2109 -> -3437 | J24: 44995 | K24: 45305 | L24: 8900.4 | M24: 5200.25 | N24: 690 | O24: 35000 | P24: Medium | Q24: Pending | R24: 0 | S24: Active
A25: Ahmed Abdullah | B25: ahmed_abdullah | C25: Business | D25: UAE | E25: Sharjah | F25: 49 | G25: Male | H25: ahmed.abdullah@company.ae | I25: =971-55-678-9012 -> -8774 | J25: 43054 | K25: 45299 | L25: 156800.6 | M25: 78000.4 | N25: 645 | O25: 165000 | P25: High | Q25: Verified | R25: 0 | S25: Active
A26: Isabella Rossi | B26: isabella_r | C26: Current | D26: Brazil | E26: SÃ£o Paulo | F26: 30 | G26: Female | H26: isabella.rossi@email.com.br | I26: =55-11-98765-4321 -> -103042 | J26: 44535 | K26: 45303 | L26: 19200.75 | M26: 8600.9 | N26: 755 | O26: 58000 | P26: Low | Q26: Verified | R26: 0 | S26: Active
A27: Takashi Yamamoto | B27: takashi_y | C27: Premium | D27: Japan | E27: Tokyo | F27: 53 | G27: Male | H27: takashi.yamamoto@mail.jp | I27: =81-70-3456-7890 -> -11335 | J27: 43159 | K27: 45301 | L27: 178900.25 | M27: 52000.8 | N27: 790 | O27: 195000 | P27: Low | Q27: Verified | R27: 0 | S27: Active
A28: Chukwuma Eze | B28: chukwuma_e | C28: Savings | D28: Nigeria | E28: Lagos | F28: 43 | G28: Male | H28: chukwuma.eze@email.ng | I28: =234-815-678-9012 -> -10271 | J28: 43660 | K28: 45302 | L28: 45600.9 | M28: 21300.6 | N28: 665 | O28: 95000 | P28: Medium | Q28: Verified | R28: 0 | S28: Active
A29: Benjamin Taylor | B29: ben_taylor | C29: Student | D29: UK | E29: London | F29: 19 | G29: Male | H29: ben.taylor@edu.ac.uk | I29: =44-79-8765-4321 -> -13121 | J29: 45207 | K29: 45304 | L29: 2250.8 | M29: 11200.75 | N29: 595 | O29: 16000 | P29: High | Q29: Pending | R29: 0 | S29: Active
A30: Mei Lin | B30: mei_lin92 | C30: Digital-Only | D30: China | E30: Guangzhou | F30: 29 | G30: Female | H30: mei.lin@mail.cn | I30: =86-137-1234-5678 -> -6963 | J30: 44788 | K30: 45305 | L30: 11200.3 | M30: 4800.4 | N30: 775 | O30: 43000 | P30: Low | Q30: Verified | R30: 0 | S30: Active
A31: Klaus Weber | B31: klaus_weber | C31: Business | D31: Germany | E31: Munich | F31: 47 | G31: Male | H31: klaus.weber@firm.de | I31: =49-172-3456789 -> -3456912 | J31: 43363 | K31: 45300 | L31: 134200.4 | M31: 65000.25 | N31: 670 | O31: 140000 | P31: High | Q31: Verified | R31: 0 | S31: Active
A32: Olivia Martin | B32: olivia_martin | C32: Joint | D32: Canada | E32: Montreal | F32: 34 | G32: Female | H32: olivia.martin@email.ca | I32: =1-514-555-154 -> -1222 | J32: 44168 | K32: 45303 | L32: 62300.6 | M32: 24500.8 | N32: 725 | O32: 98000 | P32: Medium | Q32: Verified | R32: 0 | S32: Active
A33: Arjun Desai | B33: arjun_desai | C33: Savings | D33: India | E33: Chennai | F33: 40 | G33: Male | H33: arjun.desai@email.in | I33: =91-765-432-1098 -> -2204 | J33: 43610 | K33: 45301 | L33: 51800.75 | M33: 23800.4 | N33: 700 | O33: 110000 | P33: Medium | Q33: Verified | R33: 0 | S33: Active
A34: Layla Al Qasimi | B34: layla_alq | C34: Current | D34: UAE | E34: Dubai | F34: 27 | G34: Female | H34: layla.alqasimi@email.ae | I34: =971-52-456-7890 -> -7427 | J34: 44668 | K34: 45305 | L34: 14300.2 | M34: 6200.75 | N34: 740 | O34: 49000 | P34: Low | Q34: Verified | R34: 0 | S34: Active
A35: Ricardo Oliveira | B35: ricardo_o | C35: Premium | D35: Brazil | E35: Rio de Janeiro | F35: 51 | G35: Male | H35: ricardo.oliveira@email.com.br | I35: =55-21-97654-3210 -> -100830 | J35: 42898 | K35: 45299 | L35: 198700.8 | M35: 58000.6 | N35: 780 | O35: 210000 | P35: Low | Q35: Verified | R35: 0 | S35: Active
A36: Yumi Kobayashi | B36: yumi_k | C36: Digital-Only | D36: Japan | E36: Osaka | F36: 25 | G36: Female | H36: yumi.kobayashi@mail.jp | I36: =81-90-6789-123 -> -6921 | J36: 45021 | K36: 45306 | L36: 6800.9 | M36: 3800.25 | N36: 720 | O36: 32000 | P36: Medium | Q36: Pending | R36: 0 | S36: Active
A37: Femi Balogun | B37: femi_balogun | C37: Business | D37: Nigeria | E37: Port Harcourt | F37: 46 | G37: Male | H37: femi.balogun@company.ng | I37: =234-706-789-123 -> -1384 | J37: 43342 | K37: 45300 | L37: 123800.25 | M37: 59000.75 | N37: 635 | O37: 135000 | P37: High | Q37: Verified | R37: 0 | S37: Active
A38: Charlotte Dubois | B38: charlotte_d | C38: Joint | D38: France | E38: Paris | F38: 33 | G38: Female | H38: charlotte.dubois@email.fr | I38: =33-6-1234-5678 -> -6885 | J38: 44210 | K38: 45302 | L38: 47800.4 | M38: 19500.9 | N38: 750 | O38: 92000 | P38: Low | Q38: Verified | R38: 0 | S38: Active
A39: Michael Brown | B39: mike_brown | C39: Savings | D39: US | E39: Houston | F39: 39 | G39: Male | H39: mike.brown@email.com | I39: =1-832-555-134 -> -1520 | J39: 43791 | K39: 45301 | L39: 34200.6 | M39: 12800.25 | N39: 710 | O39: 78000 | P39: Medium | Q39: Verified | R39: 0 | S39: Active
A40: Ananya Reddy | B40: ananya_reddy | C40: Student | D40: India | E40: Mumbai | F40: 22 | G40: Female | H40: ananya.reddy@edu.in | I40: =91-854-321-987 -> -2071 | J40: 45126 | K40: 45304 | L40: 1950.4 | M40: 8800.6 | N40: 605 | O40: 20000 | P40: High | Q40: Pending | R40: 0 | S40: Active
...

Sheet Data Table
A1: Full Name | B1: Username | C1: Account Type | D1: Country | E1: City | F1: Age | G1: Gender | H1: Email | I1: Phone Number | J1: Account Creation Date | K1: Last Active Date | L1: Balance (USD) | M1: Debt (USD) | N1: Credit Score | O1: Income Level (USD Annual) | P1: Risk Category | Q1: KYC Status | R1: Fraud Flag | S1: Account Status | T1: Debt Ratio | U1: Days Inactive | V1: Credit Score Band | W1: Age Group | X1: Income categories
A2: Carlos M. Rivera Jr. | B2: carlos_rivera23 | C2: Premium | D2: US | E2: New York | F2: 42 | G2: Male | H2: carlos.rivera23@email.com | I2: +1-718-555-0199 | J2: 43539 | K2: 45303 | L2: 45250.75 | M2: 12500.5 | N2: 745 | O2: 85000 | P2: Medium | Q2: Verified | R2: 0 | S2: Active | T2: =IFERROR(M2/O2,"") -> 0.14706471 | U2: =MAX($K$2:$K$1599)-K2 -> 3 | V2: =IF(N2<670,"FAIR", IF(N2<750,"GOOD",IF(N2<800,"VERY GOOD","EXCEPTIONAL"))) -> GOOD | W2: =IF(F2<25,"18-24",IF(F2<35,"25-34",IF(F2<45,"35-44",IF(F2<55,"45-54","55+")))) -> 35-44 | X2: =IF(O2<=_xlfn.QUARTILE.INC($O$2:$O$1599,1),"Low",IF(O2<=_xlfn.QUARTILE.INC($O$2:$O$1599,2),"Lower-Middle",IF(O2<=_xlfn.QUARTILE.INC($O$2:$O$1599,3),"Upper-Middle","High"))) -> Lower-Middle
A3: Aiko Tanaka | B3: aiko_tanaka | C3: Digital-Only | D3: Japan | E3: Tokyo | F3: 28 | G3: Female | H3: aiko.tanaka@mail.jp | I3: +81-90-1234-5678 | J3: 44764 | K3: 45305 | L3: 12800 | M3: 3500.25 | N3: 810 | O3: 45000 | P3: Low | Q3: Verified | R3: 0 | S3: Active | T3: =IFERROR(M3/O3,"") -> 0.077783333 | U3: =MAX($K$2:$K$1599)-K3 -> 1 | V3: =IF(N3<670,"FAIR", IF(N3<750,"GOOD",IF(N3<800,"VERY GOOD","EXCEPTIONAL"))) -> EXCEPTIONAL | W3: =IF(F3<25,"18-24",IF(F3<35,"25-34",IF(F3<45,"35-44",IF(F3<55,"45-54","55+")))) -> 25-34 | X3: =IF(O3<=_xlfn.QUARTILE.INC($O$2:$O$1599,1),"Low",IF(O3<=_xlfn.QUARTILE.INC($O$2:$O$1599,2),"Lower-Middle",IF(O3<=_xlfn.QUARTILE.INC($O$2:$O$1599,3),"Upper-Middle","High"))) -> Low
A4: Md. Rahim Uddin | B4: rahim_uddin | C4: Business | D4: India | E4: Mumbai | F4: 35 | G4: Male | H4: rahim.uddin@business.in | I4: +91-987-654-3210 | J4: 44140 | K4: 45301 | L4: 87500.8 | M4: 45000.75 | N4: 680 | O4: 120000 | P4: Medium | Q4: Pending | R4: 0 | S4: Active | T4: =IFERROR(M4/O4,"") -> 0.37500625 | U4: =MAX($K$2:$K$1599)-K4 -> 5 | V4: =IF(N4<670,"FAIR", IF(N4<750,"GOOD",IF(N4<800,"VERY GOOD","EXCEPTIONAL"))) -> GOOD | W4: =IF(F4<25,"18-24",IF(F4<35,"25-34",IF(F4<45,"35-44",IF(F4<55,"45-54","55+")))) -> 35-44 | X4: =IF(O4<=_xlfn.QUARTILE.INC($O$2:$O$1599,1),"Low",IF(O4<=_xlfn.QUARTILE.INC($O$2:$O$1599,2),"Lower-Middle",IF(O4<=_xlfn.QUARTILE.INC($O$2:$O$1599,3),"Upper-Middle","High"))) -> Lower-Middle
A5: Anna-Louise Clarke | B5: anna_clarke | C5: Joint | D5: UK | E5: London | F5: 31 | G5: Female | H5: anna.clarke@email.co.uk | I5: +44-20-7946-0958 | J5: 44457 | K5: 45304 | L5: 25600.3 | M5: 18000 | N5: 720 | O5: 75000 | P5: Low | Q5: Verified | R5: 0 | S5: Active | T5: =IFERROR(M5/O5,"") -> 0.24 | U5: =MAX($K$2:$K$1599)-K5 -> 2 | V5: =IF(N5<670,"FAIR", IF(N5<750,"GOOD",IF(N5<800,"VERY GOOD","EXCEPTIONAL"))) -> GOOD | W5: =IF(F5<25,"18-24",IF(F5<35,"25-34",IF(F5<45,"35-44",IF(F5<55,"45-54","55+")))) -> 25-34 | X5: =IF(O5<=_xlfn.QUARTILE.INC($O$2:$O$1599,1),"Low",IF(O5<=_xlfn.QUARTILE.INC($O$2:$O$1599,2),"Lower-Middle",IF(O5<=_xlfn.QUARTILE.INC($O$2:$O$1599,3),"Upper-Middle","High"))) -> Lower-Middle
A6: John 'Jack' Thompson | B6: jack_thompson | C6: Savings | D6: US | E6: Chicago | F6: 45 | G6: Male | H6: jack.thompson@email.com | I6: +1-312-555-0123 | J6: 43250 | K6: 45302 | L6: 67500.45 | M6: 25000.8 | N6: 695 | O6: 95000 | P6: Medium | Q6: Verified | R6: 0 | S6: Active | T6: =IFERROR(M6/O6,"") -> 0.26316632 | U6: =MAX($K$2:$K$1599)-K6 -> 4 | V6: =IF(N6<670,"FAIR", IF(N6<750,"GOOD",IF(N6<800,"VERY GOOD","EXCEPTIONAL"))) -> GOOD | W6: =IF(F6<25,"18-24",IF(F6<35,"25-34",IF(F6<45,"35-44",IF(F6<55,"45-54","55+")))) -> 45-54 | X6: =IF(O6<=_xlfn.QUARTILE.INC($O$2:$O$1599,1),"Low",IF(O6<=_xlfn.QUARTILE.INC($O$2:$O$1599,2),"Lower-Middle",IF(O6<=_xlfn.QUARTILE.INC($O$2:$O$1599,3),"Upper-Middle","High"))) -> Lower-Middle
A7: Wei Zhang | B7: wei_zhang95 | C7: Current | D7: China | E7: Shanghai | F7: 26 | G7: Male | H7: wei.zhang@mail.cn | I7: +86-138-0013-8000 | J7: 44971 | K7: 45306 | L7: 9800.25 | M7: 4200.5 | N7: 780 | O7: 38000 | P7: Low | Q7: Verified | R7: 0 | S7: Active | T7: =IFERROR(M7/O7,"") -> 0.11053947 | U7: =MAX($K$2:$K$1599)-K7 -> 0 | V7: =IF(N7<670,"FAIR", IF(N7<750,"GOOD",IF(N7<800,"VERY GOOD","EXCEPTIONAL"))) -> VERY GOOD | W7: =IF(F7<25,"18-24",IF(F7<35,"25-34",IF(F7<45,"35-44",IF(F7<55,"45-54","55+")))) -> 25-34 | X7: =IF(O7<=_xlfn.QUARTILE.INC($O$2:$O$1599,1),"Low",IF(O7<=_xlfn.QUARTILE.INC($O$2:$O$1599,2),"Lower-Middle",IF(O7<=_xlfn.QUARTILE.INC($O$2:$O$1599,3),"Upper-Middle","High"))) -> Low
A8: Maria Silva Santos | B8: maria_silva | C8: Savings | D8: Brazil | E8: São Paulo | F8: 39 | G8: Female | H8: maria.santos@email.com.br | I8: +55-11-91234-5678 | J8: 43689 | K8: 45300 | L8: 32400.6 | M8: 15800.25 | N8: 710 | O8: 68000 | P8: Medium | Q8: Verified | R8: 0 | S8: Active | T8: =IFERROR(M8/O8,"") -> 0.23235662 | U8: =MAX($K$2:$K$1599)-K8 -> 6 | V8: =IF(N8<670,"FAIR", IF(N8<750,"GOOD",IF(N8<800,"VERY GOOD","EXCEPTIONAL"))) -> GOOD | W8: =IF(F8<25,"18-24",IF(F8<35,"25-34",IF(F8<45,"35-44",IF(F8<55,"45-54","55+")))) -> 35-44 | X8: =IF(O8<=_xlfn.QUARTILE.INC($O$2:$O$1599,1),"Low",IF(O8<=_xlfn.QUARTILE.INC($O$2:$O$1599,2),"Lower-Middle",IF(O8<=_xlfn.QUARTILE.INC($O$2:$O$1599,3),"Upper-Middle","High"))) -> Low
A9: Chiamaka Okoro | B9: chiamaka_o | C9: Digital-Only | D9: Nigeria | E9: Lagos | F9: 24 | G9: Female | H9: chiamaka.okoro@mail.ng | I9: +234-703-456-7890 | J9: 45066 | K9: 45305 | L9: 5600.75 | M9: 3200 | N9: 650 | O9: 29000 | P9: Medium | Q9: Pending | R9: 0 | S9: Active | T9: =IFERROR(M9/O9,"") -> 0.11034483 | U9: =MAX($K$2:$K$1599)-K9 -> 1 | V9: =IF(N9<670,"FAIR", IF(N9<750,"GOOD",IF(N9<800,"VERY GOOD","EXCEPTIONAL"))) -> FAIR | W9: =IF(F9<25,"18-24",IF(F9<35,"25-34",IF(F9<45,"35-44",IF(F9<55,"45-54","55+")))) -> 18-24 | X9: =IF(O9<=_xlfn.QUARTILE.INC($O$2:$O$1599,1),"Low",IF(O9<=_xlfn.QUARTILE.INC($O$2:$O$1599,2),"Lower-Middle",IF(O9<=_xlfn.QUARTILE.INC($O$2:$O$1599,3),"Upper-Middle","High"))) -> Low
A10: Hans Müller | B10: hans_muller | C10: Business | D10: Germany | E10: Berlin | F10: 52 | G10: Male | H10: hans.muller@company.de | I10: +49-170-1234567 | J10: 43072 | K10: 45299 | L10: 124500.9 | M10: 75000.4 | N10: 665 | O10: 150000 | P10: High | Q10: Verified | R10: 0 | S10: Active | T10: =IFERROR(M10/O10,"") -> 0.50000267 | U10: =MAX($K$2:$K$1599)-K10 -> 7 | V10: =IF(N10<670,"FAIR", IF(N10<750,"GOOD",IF(N10<800,"VERY GOOD","EXCEPTIONAL"))) -> FAIR | W10: =IF(F10<25,"18-24",IF(F10<35,"25-34",IF(F10<45,"35-44",IF(F10<55,"45-54","55+")))) -> 45-54 | X10: =IF(O10<=_xlfn.QUARTILE.INC($O$2:$O$1599,1),"Low",IF(O10<=_xlfn.QUARTILE.INC($O$2:$O$1599,2),"Lower-Middle",IF(O10<=_xlfn.QUARTILE.INC($O$2:$O$1599,3),"Upper-Middle","High"))) -> Upper-Middle
A11: Fatima Al Mansouri | B11: fatima_alm | C11: Joint | D11: UAE | E11: Dubai | F11: 36 | G11: Female | H11: fatima.mansouri@email.ae | I11: +971-50-345-6789 | J11: 44311 | K11: 45303 | L11: 78900.25 | M11: 32000.75 | N11: 730 | O11: 110000 | P11: Medium | Q11: Verified | R11: 0 | S11: Active | T11: =IFERROR(M11/O11,"") -> 0.29091591 | U11: =MAX($K$2:$K$1599)-K11 -> 3 | V11: =IF(N11<670,"FAIR", IF(N11<750,"GOOD",IF(N11<800,"VERY GOOD","EXCEPTIONAL"))) -> GOOD | W11: =IF(F11<25,"18-24",IF(F11<35,"25-34",IF(F11<45,"35-44",IF(F11<55,"45-54","55+")))) -> 35-44 | X11: =IF(O11<=_xlfn.QUARTILE.INC($O$2:$O$1599,1),"Low",IF(O11<=_xlfn.QUARTILE.INC($O$2:$O$1599,2),"Lower-Middle",IF(O11<=_xlfn.QUARTILE.INC($O$2:$O$1599,3),"Upper-Middle","High"))) -> Lower-Middle
A12: James Wilson-Smith | B12: james_wilson | C12: Student | D12: Canada | E12: Toronto | F12: 21 | G12: Male | H12: james.wilson@edu.ca | I12: +1-416-555-0189 | J12: 45179 | K12: 45304 | L12: 3200.5 | M12: 12500.8 | N12: 625 | O12: 22000 | P12: High | Q12: Pending | R12: 0 | S12: Active | T12: =IFERROR(M12/O12,"") -> 0.56821818 | U12: =MAX($K$2:$K$1599)-K12 -> 2 | V12: =IF(N12<670,"FAIR", IF(N12<750,"GOOD",IF(N12<800,"VERY GOOD","EXCEPTIONAL"))) -> FAIR | W12: =IF(F12<25,"18-24",IF(F12<35,"25-34",IF(F12<45,"35-44",IF(F12<55,"45-54","55+")))) -> 18-24 | X12: =IF(O12<=_xlfn.QUARTILE.INC($O$2:$O$1599,1),"Low",IF(O12<=_xlfn.QUARTILE.INC($O$2:$O$1599,2),"Lower-Middle",IF(O12<=_xlfn.QUARTILE.INC($O$2:$O$1599,3),"Upper-Middle","High"))) -> Low
A13: Yuki Nakamura | B13: yuki_nakamura | C13: Premium | D13: Japan | E13: Osaka | F13: 48 | G13: Female | H13: yuki.nakamura@mail.jp | I13: +81-80-9876-5432 | J13: 43847 | K13: 45301 | L13: 95600.4 | M13: 28000.6 | N13: 775 | O13: 125000 | P13: Low | Q13: Verified | R13: 0 | S13: Active | T13: =IFERROR(M13/O13,"") -> 0.2240048 | U13: =MAX($K$2:$K$1599)-K13 -> 5 | V13: =IF(N13<670,"FAIR", IF(N13<750,"GOOD",IF(N13<800,"VERY GOOD","EXCEPTIONAL"))) -> VERY GOOD | W13: =IF(F13<25,"18-24",IF(F13<35,"25-34",IF(F13<45,"35-44",IF(F13<55,"45-54","55+")))) -> 45-54 | X13: =IF(O13<=_xlfn.QUARTILE.INC($O$2:$O$1599,1),"Low",IF(O13<=_xlfn.QUARTILE.INC($O$2:$O$1599,2),"Lower-Middle",IF(O13<=_xlfn.QUARTILE.INC($O$2:$O$1599,3),"Upper-Middle","High"))) -> Lower-Middle
... A1599: James Wilson | B1599: j_wilson40 | C1599: Joint | D1599: Australia | E1599: Sydney | F1599: 79 | G1599: Male | H1599: james.wilson40@email.au | I1599: +61-462-345-678 | J1599: 44795 | K1599: 45301 | L1599: 126100.75 | M1599: 77400.8 | N1599: 730 | O1599: 187000 | P1599: Medium | Q1599: Verified | R1599: 0 | S1599: Active | T1599: =IFERROR(M1599/O1599,"") -> 0.41390802 | U1599: =MAX($K$2:$K$1599)-K1599 -> 5 | V1599: =IF(N1599<670,"FAIR", IF(N1599<750,"GOOD",IF(N1599<800,"VERY GOOD","EXCEPTIONAL"))) -> GOOD | W1599: =IF(F1599<25,"18-24",IF(F1599<35,"25-34",IF(F1599<45,"35-44",IF(F1599<55,"45-54","55+")))) -> 55+ | X1599: =IF(O1599<=_xlfn.QUARTILE.INC($O$2:$O$1599,1),"Low",IF(O1599<=_xlfn.QUARTILE.INC($O$2:$O$1599,2),"Lower-Middle",IF(O1599<=_xlfn.QUARTILE.INC($O$2:$O$1599,3),"Upper-Middle","High"))) -> Upper-Middle
A1600: Fatima Zahra | B1600: f_zahra40 | C1600: Digital-Only | D1600: Pakistan | E1600: Islamabad | F1600: 64 | G1600: Female | H1600: fatima.z | T1600: =IFERROR(M1600/O1600,"") | U1600: =MAX($K$2:$K$1599)-K1600 -> 45306 | V1600: =IF(N1600<670,"FAIR", IF(N1600<750,"GOOD",IF(N1600<800,"VERY GOOD","EXCEPTIONAL"))) -> FAIR | W1600: =IF(F1600<25,"18-24",IF(F1600<35,"25-34",IF(F1600<45,"35-44",IF(F1600<55,"45-54","55+")))) -> 55+ | X1600: =IF(O1600<=_xlfn.QUARTILE.INC($O$2:$O$1599,1),"Low",IF(O1600<=_xlfn.QUARTILE.INC($O$2:$O$1599,2),"Lower-Middle",IF(O1600<=_xlfn.QUARTILE.INC($O$2:$O$1599,3),"Upper-Middle","High"))) -> Low

Sheet Pivot tables
D1: Stacked bar chart | G1: bar chart | J1: 100% stacked bar
A2: Country | B2: Count of Username | D2: Account Type | E2: Average of Balance (USD) | G2: Risk Category | H2: Average of Debt Ratio | J2: Count of Username | K2: Risk Category
A3: Brazil | B3: 45 | D3: Business | E3: 179411.91 | G3: High | H3: 0.45638133 | J3: KYC Status | K3: High | L3: Low | M3: Medium | N3: Grand Total
A4: Canada | B4: 44 | D4: Current | E4: 33615.002 | G4: Low | H4: 0.22404098 | J4: Pending | K4: 127 | M4: 126 | N4: 253
A5: China | B5: 123 | D5: Digital-Only | E5: 18689.923 | G5: Medium | H5: 0.29718027 | J5: Verified | K5: 331 | L5: 470 | M5: 544 | N5: 1345
A6: Germany | B6: 44 | D6: Joint | E6: 93282.368 | G6: Grand Total | H6: 0.32129706 | J6: Grand Total | K6: 458 | L6: 470 | M6: 670 | N6: 1598
A7: India | B7: 47 | D7: Premium | E7: 287354.49
A8: Japan | B8: 167 | D8: Savings | E8: 63502.546
A9: Mexico | B9: 80 | D9: Student | E9: 3733.0028 | G9: Donut Chart
A10: Nigeria | B10: 125 | D10: Grand Total | E10: 102590.24 | G10: Risk Category | H10: Count of Username
A11: Pakistan | B11: 81 | G11: High | H11: 458 | J11: Income categories | K11: Average of Balance (USD) | L11: Average of Debt (USD) | M11: Average of Credit Score
A12: UK | B12: 45 | G12: Low | H12: 470 | J12: High | K12: 231739.5 | L12: 101834.73 | M12: 734.49749
A13: US | B13: 87 | D13: Account Type | E13: Average of Debt (USD) | G13: Medium | H13: 670 | J13: Low | K13: 14363.478 | L13: 10418.522 | M13: 683.01746
A14: Grand Total | B14: 888 | D14: Business | E14: 99184.318 | G14: Grand Total | H14: 1598 | J14: Lower-Middle | K14: 54201.747 | L14: 27113.68 | M14: 718.55528
D15: Current | E15: 13252.651 | J15: Upper-Middle | K15: 110660.41 | L15: 59627.494 | M15: 709.25187
D16: Digital-Only | E16: 10006.425 | J16: Grand Total | K16: 102590.24 | L16: 49693.315 | M16: 711.27347
A17: Risk Category | B17: Count of Username | D17: Joint | E17: 48785.47
A18: High | B18: 458 | D18: Premium | E18: 94744.638 | G18: Country | H18: Sum of Balance (USD) | J18: 100% stacked bar | P18: Total customers
A19: Low | B19: 470 | D19: Savings | E19: 37116.938 | G19: Brazil | H19: 11042139 | J19: Count of Username | K19: Risk Category | P19: Average balance
A20: Medium | B20: 670 | D20: Student | E20: 12872.976 | G20: China | H20: 21757479 | J20: Credit Score Band | K20: High | L20: Low | M20: Medium | N20: Grand Total
A21: Grand Total | B21: 1598 | D21: Grand Total | E21: 49693.315 | G21: India | H21: 8917685.7 | J21: EXCEPTIONAL | L21: 166 | N21: 166
G22: Ireland | H22: 5950817.8 | J22: FAIR | K22: 293 | M22: 44 | N22: 337
G23: Japan | H23: 14215928 | J23: GOOD | K23: 165 | L23: 174 | M23: 545 | N23: 884
A24: Account Type | B24: Average of Debt Ratio | D24: Age Group | E24: Average of Balance (USD) | G24: Mexico | H24: 14809867 | J24: VERY GOOD | L24: 130 | M24: 81 | N24: 211
A25: Business | B25: 0.48761985 | D25: 18-24 | E25: 2567.8868 | G25: Nigeria | H25: 16693354 | J25: Grand Total | K25: 458 | L25: 470 | M25: 670 | N25: 1598
A26: Current | B26: 0.1669235 | D26: 25-34 | E26: 12329.842 | G26: Pakistan | H26: 8461095.7
A27: Digital-Only | B27: 0.17341973 | D27: 35-44 | E27: 38903.229 | G27: Singapore | H27: 6953924.9
A28: Joint | B28: 0.32561246 | D28: 45-54 | E28: 74722.193 | G28: UK | H28: 7267276.8 | J28: Donut Chart
A29: Premium | B29: 0.31467581 | D29: 55+ | E29: 145984.3 | G29: Grand Total | H29: 1.1606957e+08 | J29: KYC Status | K29: Count of Username
A30: Savings | B30: 0.32906583 | D30: Grand Total | E30: 102590.24 | K30: 1
A31: Student | B31: 0.37407768 | J31: Pending | K31: 253
A32: Grand Total | B32: 0.32129706 | J32: Verified | K32: 1345
D33: Count of Username | J33: Grand Total | K33: 1599
D34: 1599
D37: Average of Balance (USD)
D38: 102590.24
D41: Average of Credit Score
D42: 711.27347
D45: Average of Debt Ratio
D46: 0.32129706
...

Sheet Dashboard
A1: Global Banking Customer Risk Dashboard | N1: Total Customers | R1: Average Balance | V1: Avg Credit Score | Z1: Avg Debt Ratio | AD1: High Risk Users
N2: ='Pivot tables'!D34 -> 1599 | R2: ='Pivot tables'!D38 -> 102590.24 | V2: ='Pivot tables'!D42 -> 711.27347 | Z2: ='Pivot tables'!D46 -> 0.32129706 | AD2: ='Pivot tables'!E50 -> 0.28660826
A3: Global Banking Customer Risk Dashboard
A4: Global Banking Customer Risk Dashboard
